Workbook

Sheet GAME
B1: TRADING GAME SOLVER
B3: YOUR INPUTS | E3: SETTINGS
B4: Your Card: | E4: Bluff Prior (p): | F4: 0.7
B5: Central 1: | E5: Sigma: | F5: 3
B6: Central 2:
B7: Central 3:
B9: YOUR EV
B10: Known Cards: | C10: =1+COUNTA(C5:C7)
B11: Known Sum: | C11: =C4+SUM(C5:C7)
B12: Unknowns in Play: | C12: =7-COUNTA(C5:C7)
B13: Remaining Pool Mean: | C13: =(130-C11)/(17-C10)
B15: Fair Total (EV): | C15: =IF(C4="","",C11+C12*C13)
B16: Fair Mid (rounded): | C16: =IF(C15="","",ROUND(C15,0))
B17: Your Bid: | C17: =IF(C16="","",C16-1)
B18: Your Ask: | C18: =IF(C16="","",C16+1)
B20: DECISION HELPER
B21: Offered Bid:
B22: Offered Ask:
B24: Buy EV: | C24: =IF(OR(C15="",C22=""),"",C15-C22)
B25: Sell EV: | C25: =IF(OR(C15="",C21=""),"",C21-C15)
B27: RECOMMENDATION: | C27: =IF(OR(C24="",C25=""),"—",IF(AND(C24>0,C24>=C25),"BUY",IF(C25>0,"SELL","WALK")))
B29: OPPONENT INFERENCE
B30: Player | C30: Obs. Mid | D30: Likely Card | E30: Confidence
B31: Opponent 1 | D31: =IF(C31="","—",INDEX(INFERENCE!A4:A20,MATCH(MAX(INFERENCE!G4:G20),INFERENCE!G4:G20,0))) | E31: =IF(C31="","—",MAX(INFERENCE!G4:G20))
B32: Opponent 2 | D32: =IF(C32="","—",INDEX(INFERENCE!A23:A39,MATCH(MAX(INFERENCE!G23:G39),INFERENCE!G23:G39,0))) | E32: =IF(C32="","—",MAX(INFERENCE!G23:G39))
B33: Opponent 3 | D33: =IF(C33="","—",INDEX(INFERENCE!A42:A58,MATCH(MAX(INFERENCE!G42:G58),INFERENCE!G42:G58,0))) | E33: =IF(C33="","—",MAX(INFERENCE!G42:G58))
B34: Opponent 4 | D34: =IF(C34="","—",INDEX(INFERENCE!A61:A77,MATCH(MAX(INFERENCE!G61:G77),INFERENCE!G61:G77,0))) | E34: =IF(C34="","—",MAX(INFERENCE!G61:G77))

Sheet INFERENCE
A2: Opponent 1 | C2: Obs Mid → GAME!C31
A3: Card | B3: Poss? | C3: Naive EV | D3: Bluff EV | E3: L(naive) | F3: L(bluff) | G3: P(card)
A4: -10 | B4: =AND(A4<>GAME!C4,OR(GAME!C5="",A4<>GAME!C5),OR(GAME!C6="",A4<>GAME!C6),OR(GAME!C7="",A4<>GAME!C7)) | C4: =A4+SUM(GAME!C5:C7)+(7-COUNTA(GAME!C5:C7))*(130-A4-SUM(GAME!C5:C7))/(16-COUNTA(GAME!C5:C7)) | D4: =IF(A4>7.65,C4-REFERENCE!B5,C4+REFERENCE!B5) | E4: =IF(AND(B4,GAME!C31<>""),EXP(-((C4-GAME!C31)^2)/(2*GAME!F5^2)),0) | F4: =IF(AND(B4,GAME!C31<>""),EXP(-((D4-GAME!C31)^2)/(2*GAME!F5^2)),0) | G4: =IF(GAME!C31="",IF(B4,1/COUNTIF(B4:B20,TRUE),0),IF(B4,(GAME!F4*E4+(1-GAME!F4)*F4)/SUMPRODUCT(GAME!F4*E4:E20+(1-GAME!F4)*F4:F20),0))
A5: 1 | B5: =AND(A5<>GAME!C4,OR(GAME!C5="",A5<>GAME!C5),OR(GAME!C6="",A5<>GAME!C6),OR(GAME!C7="",A5<>GAME!C7)) | C5: =A5+SUM(GAME!C5:C7)+(7-COUNTA(GAME!C5:C7))*(130-A5-SUM(GAME!C5:C7))/(16-COUNTA(GAME!C5:C7)) | D5: =IF(A5>7.65,C5-REFERENCE!B5,C5+REFERENCE!B5) | E5: =IF(AND(B5,GAME!C31<>""),EXP(-((C5-GAME!C31)^2)/(2*GAME!F5^2)),0) | F5: =IF(AND(B5,GAME!C31<>""),EXP(-((D5-GAME!C31)^2)/(2*GAME!F5^2)),0) | G5: =IF(GAME!C31="",IF(B5,1/COUNTIF(B4:B20,TRUE),0),IF(B5,(GAME!F4*E5+(1-GAME!F4)*F5)/SUMPRODUCT(GAME!F4*E4:E20+(1-GAME!F4)*F4:F20),0))
A6: 2 | B6: =AND(A6<>GAME!C4,OR(GAME!C5="",A6<>GAME!C5),OR(GAME!C6="",A6<>GAME!C6),OR(GAME!C7="",A6<>GAME!C7)) | C6: =A6+SUM(GAME!C5:C7)+(7-COUNTA(GAME!C5:C7))*(130-A6-SUM(GAME!C5:C7))/(16-COUNTA(GAME!C5:C7)) | D6: =IF(A6>7.65,C6-REFERENCE!B5,C6+REFERENCE!B5) | E6: =IF(AND(B6,GAME!C31<>""),EXP(-((C6-GAME!C31)^2)/(2*GAME!F5^2)),0) | F6: =IF(AND(B6,GAME!C31<>""),EXP(-((D6-GAME!C31)^2)/(2*GAME!F5^2)),0) | G6: =IF(GAME!C31="",IF(B6,1/COUNTIF(B4:B20,TRUE),0),IF(B6,(GAME!F4*E6+(1-GAME!F4)*F6)/SUMPRODUCT(GAME!F4*E4:E20+(1-GAME!F4)*F4:F20),0))
A7: 3 | B7: =AND(A7<>GAME!C4,OR(GAME!C5="",A7<>GAME!C5),OR(GAME!C6="",A7<>GAME!C6),OR(GAME!C7="",A7<>GAME!C7)) | C7: =A7+SUM(GAME!C5:C7)+(7-COUNTA(GAME!C5:C7))*(130-A7-SUM(GAME!C5:C7))/(16-COUNTA(GAME!C5:C7)) | D7: =IF(A7>7.65,C7-REFERENCE!B5,C7+REFERENCE!B5) | E7: =IF(AND(B7,GAME!C31<>""),EXP(-((C7-GAME!C31)^2)/(2*GAME!F5^2)),0) | F7: =IF(AND(B7,GAME!C31<>""),EXP(-((D7-GAME!C31)^2)/(2*GAME!F5^2)),0) | G7: =IF(GAME!C31="",IF(B7,1/COUNTIF(B4:B20,TRUE),0),IF(B7,(GAME!F4*E7+(1-GAME!F4)*F7)/SUMPRODUCT(GAME!F4*E4:E20+(1-GAME!F4)*F4:F20),0))
A8: 4 | B8: =AND(A8<>GAME!C4,OR(GAME!C5="",A8<>GAME!C5),OR(GAME!C6="",A8<>GAME!C6),OR(GAME!C7="",A8<>GAME!C7)) | C8: =A8+SUM(GAME!C5:C7)+(7-COUNTA(GAME!C5:C7))*(130-A8-SUM(GAME!C5:C7))/(16-COUNTA(GAME!C5:C7)) | D8: =IF(A8>7.65,C8-REFERENCE!B5,C8+REFERENCE!B5) | E8: =IF(AND(B8,GAME!C31<>""),EXP(-((C8-GAME!C31)^2)/(2*GAME!F5^2)),0) | F8: =IF(AND(B8,GAME!C31<>""),EXP(-((D8-GAME!C31)^2)/(2*GAME!F5^2)),0) | G8: =IF(GAME!C31="",IF(B8,1/COUNTIF(B4:B20,TRUE),0),IF(B8,(GAME!F4*E8+(1-GAME!F4)*F8)/SUMPRODUCT(GAME!F4*E4:E20+(1-GAME!F4)*F4:F20),0))
A9: 5 | B9: =AND(A9<>GAME!C4,OR(GAME!C5="",A9<>GAME!C5),OR(GAME!C6="",A9<>GAME!C6),OR(GAME!C7="",A9<>GAME!C7)) | C9: =A9+SUM(GAME!C5:C7)+(7-COUNTA(GAME!C5:C7))*(130-A9-SUM(GAME!C5:C7))/(16-COUNTA(GAME!C5:C7)) | D9: =IF(A9>7.65,C9-REFERENCE!B5,C9+REFERENCE!B5) | E9: =IF(AND(B9,GAME!C31<>""),EXP(-((C9-GAME!C31)^2)/(2*GAME!F5^2)),0) | F9: =IF(AND(B9,GAME!C31<>""),EXP(-((D9-GAME!C31)^2)/(2*GAME!F5^2)),0) | G9: =IF(GAME!C31="",IF(B9,1/COUNTIF(B4:B20,TRUE),0),IF(B9,(GAME!F4*E9+(1-GAME!F4)*F9)/SUMPRODUCT(GAME!F4*E4:E20+(1-GAME!F4)*F4:F20),0))
A10: 6 | B10: =AND(A10<>GAME!C4,OR(GAME!C5="",A10<>GAME!C5),OR(GAME!C6="",A10<>GAME!C6),OR(GAME!C7="",A10<>GAME!C7)) | C10: =A10+SUM(GAME!C5:C7)+(7-COUNTA(GAME!C5:C7))*(130-A10-SUM(GAME!C5:C7))/(16-COUNTA(GAME!C5:C7)) | D10: =IF(A10>7.65,C10-REFERENCE!B5,C10+REFERENCE!B5) | E10: =IF(AND(B10,GAME!C31<>""),EXP(-((C10-GAME!C31)^2)/(2*GAME!F5^2)),0) | F10: =IF(AND(B10,GAME!C31<>""),EXP(-((D10-GAME!C31)^2)/(2*GAME!F5^2)),0) | G10: =IF(GAME!C31="",IF(B10,1/COUNTIF(B4:B20,TRUE),0),IF(B10,(GAME!F4*E10+(1-GAME!F4)*F10)/SUMPRODUCT(GAME!F4*E4:E20+(1-GAME!F4)*F4:F20),0))
A11: 7 | B11: =AND(A11<>GAME!C4,OR(GAME!C5="",A11<>GAME!C5),OR(GAME!C6="",A11<>GAME!C6),OR(GAME!C7="",A11<>GAME!C7)) | C11: =A11+SUM(GAME!C5:C7)+(7-COUNTA(GAME!C5:C7))*(130-A11-SUM(GAME!C5:C7))/(16-COUNTA(GAME!C5:C7)) | D11: =IF(A11>7.65,C11-REFERENCE!B5,C11+REFERENCE!B5) | E11: =IF(AND(B11,GAME!C31<>""),EXP(-((C11-GAME!C31)^2)/(2*GAME!F5^2)),0) | F11: =IF(AND(B11,GAME!C31<>""),EXP(-((D11-GAME!C31)^2)/(2*GAME!F5^2)),0) | G11: =IF(GAME!C31="",IF(B11,1/COUNTIF(B4:B20,TRUE),0),IF(B11,(GAME!F4*E11+(1-GAME!F4)*F11)/SUMPRODUCT(GAME!F4*E4:E20+(1-GAME!F4)*F4:F20),0))
A12: 8 | B12: =AND(A12<>GAME!C4,OR(GAME!C5="",A12<>GAME!C5),OR(GAME!C6="",A12<>GAME!C6),OR(GAME!C7="",A12<>GAME!C7)) | C12: =A12+SUM(GAME!C5:C7)+(7-COUNTA(GAME!C5:C7))*(130-A12-SUM(GAME!C5:C7))/(16-COUNTA(GAME!C5:C7)) | D12: =IF(A12>7.65,C12-REFERENCE!B5,C12+REFERENCE!B5) | E12: =IF(AND(B12,GAME!C31<>""),EXP(-((C12-GAME!C31)^2)/(2*GAME!F5^2)),0) | F12: =IF(AND(B12,GAME!C31<>""),EXP(-((D12-GAME!C31)^2)/(2*GAME!F5^2)),0) | G12: =IF(GAME!C31="",IF(B12,1/COUNTIF(B4:B20,TRUE),0),IF(B12,(GAME!F4*E12+(1-GAME!F4)*F12)/SUMPRODUCT(GAME!F4*E4:E20+(1-GAME!F4)*F4:F20),0))
A13: 9 | B13: =AND(A13<>GAME!C4,OR(GAME!C5="",A13<>GAME!C5),OR(GAME!C6="",A13<>GAME!C6),OR(GAME!C7="",A13<>GAME!C7)) | C13: =A13+SUM(GAME!C5:C7)+(7-COUNTA(GAME!C5:C7))*(130-A13-SUM(GAME!C5:C7))/(16-COUNTA(GAME!C5:C7)) | D13: =IF(A13>7.65,C13-REFERENCE!B5,C13+REFERENCE!B5) | E13: =IF(AND(B13,GAME!C31<>""),EXP(-((C13-GAME!C31)^2)/(2*GAME!F5^2)),0) | F13: =IF(AND(B13,GAME!C31<>""),EXP(-((D13-GAME!C31)^2)/(2*GAME!F5^2)),0) | G13: =IF(GAME!C31="",IF(B13,1/COUNTIF(B4:B20,TRUE),0),IF(B13,(GAME!F4*E13+(1-GAME!F4)*F13)/SUMPRODUCT(GAME!F4*E4:E20+(1-GAME!F4)*F4:F20),0))
A14: 10 | B14: =AND(A14<>GAME!C4,OR(GAME!C5="",A14<>GAME!C5),OR(GAME!C6="",A14<>GAME!C6),OR(GAME!C7="",A14<>GAME!C7)) | C14: =A14+SUM(GAME!C5:C7)+(7-COUNTA(GAME!C5:C7))*(130-A14-SUM(GAME!C5:C7))/(16-COUNTA(GAME!C5:C7)) | D14: =IF(A14>7.65,C14-REFERENCE!B5,C14+REFERENCE!B5) | E14: =IF(AND(B14,GAME!C31<>""),EXP(-((C14-GAME!C31)^2)/(2*GAME!F5^2)),0) | F14: =IF(AND(B14,GAME!C31<>""),EXP(-((D14-GAME!C31)^2)/(2*GAME!F5^2)),0) | G14: =IF(GAME!C31="",IF(B14,1/COUNTIF(B4:B20,TRUE),0),IF(B14,(GAME!F4*E14+(1-GAME!F4)*F14)/SUMPRODUCT(GAME!F4*E4:E20+(1-GAME!F4)*F4:F20),0))
A15: 11 | B15: =AND(A15<>GAME!C4,OR(GAME!C5="",A15<>GAME!C5),OR(GAME!C6="",A15<>GAME!C6),OR(GAME!C7="",A15<>GAME!C7)) | C15: =A15+SUM(GAME!C5:C7)+(7-COUNTA(GAME!C5:C7))*(130-A15-SUM(GAME!C5:C7))/(16-COUNTA(GAME!C5:C7)) | D15: =IF(A15>7.65,C15-REFERENCE!B5,C15+REFERENCE!B5) | E15: =IF(AND(B15,GAME!C31<>""),EXP(-((C15-GAME!C31)^2)/(2*GAME!F5^2)),0) | F15: =IF(AND(B15,GAME!C31<>""),EXP(-((D15-GAME!C31)^2)/(2*GAME!F5^2)),0) | G15: =IF(GAME!C31="",IF(B15,1/COUNTIF(B4:B20,TRUE),0),IF(B15,(GAME!F4*E15+(1-GAME!F4)*F15)/SUMPRODUCT(GAME!F4*E4:E20+(1-GAME!F4)*F4:F20),0))
A16: 12 | B16: =AND(A16<>GAME!C4,OR(GAME!C5="",A16<>GAME!C5),OR(GAME!C6="",A16<>GAME!C6),OR(GAME!C7="",A16<>GAME!C7)) | C16: =A16+SUM(GAME!C5:C7)+(7-COUNTA(GAME!C5:C7))*(130-A16-SUM(GAME!C5:C7))/(16-COUNTA(GAME!C5:C7)) | D16: =IF(A16>7.65,C16-REFERENCE!B5,C16+REFERENCE!B5) | E16: =IF(AND(B16,GAME!C31<>""),EXP(-((C16-GAME!C31)^2)/(2*GAME!F5^2)),0) | F16: =IF(AND(B16,GAME!C31<>""),EXP(-((D16-GAME!C31)^2)/(2*GAME!F5^2)),0) | G16: =IF(GAME!C31="",IF(B16,1/COUNTIF(B4:B20,TRUE),0),IF(B16,(GAME!F4*E16+(1-GAME!F4)*F16)/SUMPRODUCT(GAME!F4*E4:E20+(1-GAME!F4)*F4:F20),0))
A17: 13 | B17: =AND(A17<>GAME!C4,OR(GAME!C5="",A17<>GAME!C5),OR(GAME!C6="",A17<>GAME!C6),OR(GAME!C7="",A17<>GAME!C7)) | C17: =A17+SUM(GAME!C5:C7)+(7-COUNTA(GAME!C5:C7))*(130-A17-SUM(GAME!C5:C7))/(16-COUNTA(GAME!C5:C7)) | D17: =IF(A17>7.65,C17-REFERENCE!B5,C17+REFERENCE!B5) | E17: =IF(AND(B17,GAME!C31<>""),EXP(-((C17-GAME!C31)^2)/(2*GAME!F5^2)),0) | F17: =IF(AND(B17,GAME!C31<>""),EXP(-((D17-GAME!C31)^2)/(2*GAME!F5^2)),0) | G17: =IF(GAME!C31="",IF(B17,1/COUNTIF(B4:B20,TRUE),0),IF(B17,(GAME!F4*E17+(1-GAME!F4)*F17)/SUMPRODUCT(GAME!F4*E4:E20+(1-GAME!F4)*F4:F20),0))
A18: 14 | B18: =AND(A18<>GAME!C4,OR(GAME!C5="",A18<>GAME!C5),OR(GAME!C6="",A18<>GAME!C6),OR(GAME!C7="",A18<>GAME!C7)) | C18: =A18+SUM(GAME!C5:C7)+(7-COUNTA(GAME!C5:C7))*(130-A18-SUM(GAME!C5:C7))/(16-COUNTA(GAME!C5:C7)) | D18: =IF(A18>7.65,C18-REFERENCE!B5,C18+REFERENCE!B5) | E18: =IF(AND(B18,GAME!C31<>""),EXP(-((C18-GAME!C31)^2)/(2*GAME!F5^2)),0) | F18: =IF(AND(B18,GAME!C31<>""),EXP(-((D18-GAME!C31)^2)/(2*GAME!F5^2)),0) | G18: =IF(GAME!C31="",IF(B18,1/COUNTIF(B4:B20,TRUE),0),IF(B18,(GAME!F4*E18+(1-GAME!F4)*F18)/SUMPRODUCT(GAME!F4*E4:E20+(1-GAME!F4)*F4:F20),0))
A19: 15 | B19: =AND(A19<>GAME!C4,OR(GAME!C5="",A19<>GAME!C5),OR(GAME!C6="",A19<>GAME!C6),OR(GAME!C7="",A19<>GAME!C7)) | C19: =A19+SUM(GAME!C5:C7)+(7-COUNTA(GAME!C5:C7))*(130-A19-SUM(GAME!C5:C7))/(16-COUNTA(GAME!C5:C7)) | D19: =IF(A19>7.65,C19-REFERENCE!B5,C19+REFERENCE!B5) | E19: =IF(AND(B19,GAME!C31<>""),EXP(-((C19-GAME!C31)^2)/(2*GAME!F5^2)),0) | F19: =IF(AND(B19,GAME!C31<>""),EXP(-((D19-GAME!C31)^2)/(2*GAME!F5^2)),0) | G19: =IF(GAME!C31="",IF(B19,1/COUNTIF(B4:B20,TRUE),0),IF(B19,(GAME!F4*E19+(1-GAME!F4)*F19)/SUMPRODUCT(GAME!F4*E4:E20+(1-GAME!F4)*F4:F20),0))
A20: 20 | B20: =AND(A20<>GAME!C4,OR(GAME!C5="",A20<>GAME!C5),OR(GAME!C6="",A20<>GAME!C6),OR(GAME!C7="",A20<>GAME!C7)) | C20: =A20+SUM(GAME!C5:C7)+(7-COUNTA(GAME!C5:C7))*(130-A20-SUM(GAME!C5:C7))/(16-COUNTA(GAME!C5:C7)) | D20: =IF(A20>7.65,C20-REFERENCE!B5,C20+REFERENCE!B5) | E20: =IF(AND(B20,GAME!C31<>""),EXP(-((C20-GAME!C31)^2)/(2*GAME!F5^2)),0) | F20: =IF(AND(B20,GAME!C31<>""),EXP(-((D20-GAME!C31)^2)/(2*GAME!F5^2)),0) | G20: =IF(GAME!C31="",IF(B20,1/COUNTIF(B4:B20,TRUE),0),IF(B20,(GAME!F4*E20+(1-GAME!F4)*F20)/SUMPRODUCT(GAME!F4*E4:E20+(1-GAME!F4)*F4:F20),0))
A21: Opponent 2 | C21: Obs Mid → GAME!C32
A22: Card | B22: Poss? | C22: Naive EV | D22: Bluff EV | E22: L(naive) | F22: L(bluff) | G22: P(card)
A23: -10 | B23: =AND(A23<>GAME!C4,OR(GAME!C5="",A23<>GAME!C5),OR(GAME!C6="",A23<>GAME!C6),OR(GAME!C7="",A23<>GAME!C7)) | C23: =A23+SUM(GAME!C5:C7)+(7-COUNTA(GAME!C5:C7))*(130-A23-SUM(GAME!C5:C7))/(16-COUNTA(GAME!C5:C7)) | D23: =IF(A23>7.65,C23-REFERENCE!B5,C23+REFERENCE!B5) | E23: =IF(AND(B23,GAME!C32<>""),EXP(-((C23-GAME!C32)^2)/(2*GAME!F5^2)),0) | F23: =IF(AND(B23,GAME!C32<>""),EXP(-((D23-GAME!C32)^2)/(2*GAME!F5^2)),0) | G23: =IF(GAME!C32="",IF(B23,1/COUNTIF(B23:B39,TRUE),0),IF(B23,(GAME!F4*E23+(1-GAME!F4)*F23)/SUMPRODUCT(GAME!F4*E23:E39+(1-GAME!F4)*F23:F39),0))
A24: 1 | B24: =AND(A24<>GAME!C4,OR(GAME!C5="",A24<>GAME!C5),OR(GAME!C6="",A24<>GAME!C6),OR(GAME!C7="",A24<>GAME!C7)) | C24: =A24+SUM(GAME!C5:C7)+(7-COUNTA(GAME!C5:C7))*(130-A24-SUM(GAME!C5:C7))/(16-COUNTA(GAME!C5:C7)) | D24: =IF(A24>7.65,C24-REFERENCE!B5,C24+REFERENCE!B5) | E24: =IF(AND(B24,GAME!C32<>""),EXP(-((C24-GAME!C32)^2)/(2*GAME!F5^2)),0) | F24: =IF(AND(B24,GAME!C32<>""),EXP(-((D24-GAME!C32)^2)/(2*GAME!F5^2)),0) | G24: =IF(GAME!C32="",IF(B24,1/COUNTIF(B23:B39,TRUE),0),IF(B24,(GAME!F4*E24+(1-GAME!F4)*F24)/SUMPRODUCT(GAME!F4*E23:E39+(1-GAME!F4)*F23:F39),0))
A25: 2 | B25: =AND(A25<>GAME!C4,OR(GAME!C5="",A25<>GAME!C5),OR(GAME!C6="",A25<>GAME!C6),OR(GAME!C7="",A25<>GAME!C7)) | C25: =A25+SUM(GAME!C5:C7)+(7-COUNTA(GAME!C5:C7))*(130-A25-SUM(GAME!C5:C7))/(16-COUNTA(GAME!C5:C7)) | D25: =IF(A25>7.65,C25-REFERENCE!B5,C25+REFERENCE!B5) | E25: =IF(AND(B25,GAME!C32<>""),EXP(-((C25-GAME!C32)^2)/(2*GAME!F5^2)),0) | F25: =IF(AND(B25,GAME!C32<>""),EXP(-((D25-GAME!C32)^2)/(2*GAME!F5^2)),0) | G25: =IF(GAME!C32="",IF(B25,1/COUNTIF(B23:B39,TRUE),0),IF(B25,(GAME!F4*E25+(1-GAME!F4)*F25)/SUMPRODUCT(GAME!F4*E23:E39+(1-GAME!F4)*F23:F39),0))
A26: 3 | B26: =AND(A26<>GAME!C4,OR(GAME!C5="",A26<>GAME!C5),OR(GAME!C6="",A26<>GAME!C6),OR(GAME!C7="",A26<>GAME!C7)) | C26: =A26+SUM(GAME!C5:C7)+(7-COUNTA(GAME!C5:C7))*(130-A26-SUM(GAME!C5:C7))/(16-COUNTA(GAME!C5:C7)) | D26: =IF(A26>7.65,C26-REFERENCE!B5,C26+REFERENCE!B5) | E26: =IF(AND(B26,GAME!C32<>""),EXP(-((C26-GAME!C32)^2)/(2*GAME!F5^2)),0) | F26: =IF(AND(B26,GAME!C32<>""),EXP(-((D26-GAME!C32)^2)/(2*GAME!F5^2)),0) | G26: =IF(GAME!C32="",IF(B26,1/COUNTIF(B23:B39,TRUE),0),IF(B26,(GAME!F4*E26+(1-GAME!F4)*F26)/SUMPRODUCT(GAME!F4*E23:E39+(1-GAME!F4)*F23:F39),0))
A27: 4 | B27: =AND(A27<>GAME!C4,OR(GAME!C5="",A27<>GAME!C5),OR(GAME!C6="",A27<>GAME!C6),OR(GAME!C7="",A27<>GAME!C7)) | C27: =A27+SUM(GAME!C5:C7)+(7-COUNTA(GAME!C5:C7))*(130-A27-SUM(GAME!C5:C7))/(16-COUNTA(GAME!C5:C7)) | D27: =IF(A27>7.65,C27-REFERENCE!B5,C27+REFERENCE!B5) | E27: =IF(AND(B27,GAME!C32<>""),EXP(-((C27-GAME!C32)^2)/(2*GAME!F5^2)),0) | F27: =IF(AND(B27,GAME!C32<>""),EXP(-((D27-GAME!C32)^2)/(2*GAME!F5^2)),0) | G27: =IF(GAME!C32="",IF(B27,1/COUNTIF(B23:B39,TRUE),0),IF(B27,(GAME!F4*E27+(1-GAME!F4)*F27)/SUMPRODUCT(GAME!F4*E23:E39+(1-GAME!F4)*F23:F39),0))
A28: 5 | B28: =AND(A28<>GAME!C4,OR(GAME!C5="",A28<>GAME!C5),OR(GAME!C6="",A28<>GAME!C6),OR(GAME!C7="",A28<>GAME!C7)) | C28: =A28+SUM(GAME!C5:C7)+(7-COUNTA(GAME!C5:C7))*(130-A28-SUM(GAME!C5:C7))/(16-COUNTA(GAME!C5:C7)) | D28: =IF(A28>7.65,C28-REFERENCE!B5,C28+REFERENCE!B5) | E28: =IF(AND(B28,GAME!C32<>""),EXP(-((C28-GAME!C32)^2)/(2*GAME!F5^2)),0) | F28: =IF(AND(B28,GAME!C32<>""),EXP(-((D28-GAME!C32)^2)/(2*GAME!F5^2)),0) | G28: =IF(GAME!C32="",IF(B28,1/COUNTIF(B23:B39,TRUE),0),IF(B28,(GAME!F4*E28+(1-GAME!F4)*F28)/SUMPRODUCT(GAME!F4*E23:E39+(1-GAME!F4)*F23:F39),0))
A29: 6 | B29: =AND(A29<>GAME!C4,OR(GAME!C5="",A29<>GAME!C5),OR(GAME!C6="",A29<>GAME!C6),OR(GAME!C7="",A29<>GAME!C7)) | C29: =A29+SUM(GAME!C5:C7)+(7-COUNTA(GAME!C5:C7))*(130-A29-SUM(GAME!C5:C7))/(16-COUNTA(GAME!C5:C7)) | D29: =IF(A29>7.65,C29-REFERENCE!B5,C29+REFERENCE!B5) | E29: =IF(AND(B29,GAME!C32<>""),EXP(-((C29-GAME!C32)^2)/(2*GAME!F5^2)),0) | F29: =IF(AND(B29,GAME!C32<>""),EXP(-((D29-GAME!C32)^2)/(2*GAME!F5^2)),0) | G29: =IF(GAME!C32="",IF(B29,1/COUNTIF(B23:B39,TRUE),0),IF(B29,(GAME!F4*E29+(1-GAME!F4)*F29)/SUMPRODUCT(GAME!F4*E23:E39+(1-GAME!F4)*F23:F39),0))
A30: 7 | B30: =AND(A30<>GAME!C4,OR(GAME!C5="",A30<>GAME!C5),OR(GAME!C6="",A30<>GAME!C6),OR(GAME!C7="",A30<>GAME!C7)) | C30: =A30+SUM(GAME!C5:C7)+(7-COUNTA(GAME!C5:C7))*(130-A30-SUM(GAME!C5:C7))/(16-COUNTA(GAME!C5:C7)) | D30: =IF(A30>7.65,C30-REFERENCE!B5,C30+REFERENCE!B5) | E30: =IF(AND(B30,GAME!C32<>""),EXP(-((C30-GAME!C32)^2)/(2*GAME!F5^2)),0) | F30: =IF(AND(B30,GAME!C32<>""),EXP(-((D30-GAME!C32)^2)/(2*GAME!F5^2)),0) | G30: =IF(GAME!C32="",IF(B30,1/COUNTIF(B23:B39,TRUE),0),IF(B30,(GAME!F4*E30+(1-GAME!F4)*F30)/SUMPRODUCT(GAME!F4*E23:E39+(1-GAME!F4)*F23:F39),0))
A31: 8 | B31: =AND(A31<>GAME!C4,OR(GAME!C5="",A31<>GAME!C5),OR(GAME!C6="",A31<>GAME!C6),OR(GAME!C7="",A31<>GAME!C7)) | C31: =A31+SUM(GAME!C5:C7)+(7-COUNTA(GAME!C5:C7))*(130-A31-SUM(GAME!C5:C7))/(16-COUNTA(GAME!C5:C7)) | D31: =IF(A31>7.65,C31-REFERENCE!B5,C31+REFERENCE!B5) | E31: =IF(AND(B31,GAME!C32<>""),EXP(-((C31-GAME!C32)^2)/(2*GAME!F5^2)),0) | F31: =IF(AND(B31,GAME!C32<>""),EXP(-((D31-GAME!C32)^2)/(2*GAME!F5^2)),0) | G31: =IF(GAME!C32="",IF(B31,1/COUNTIF(B23:B39,TRUE),0),IF(B31,(GAME!F4*E31+(1-GAME!F4)*F31)/SUMPRODUCT(GAME!F4*E23:E39+(1-GAME!F4)*F23:F39),0))
A32: 9 | B32: =AND(A32<>GAME!C4,OR(GAME!C5="",A32<>GAME!C5),OR(GAME!C6="",A32<>GAME!C6),OR(GAME!C7="",A32<>GAME!C7)) | C32: =A32+SUM(GAME!C5:C7)+(7-COUNTA(GAME!C5:C7))*(130-A32-SUM(GAME!C5:C7))/(16-COUNTA(GAME!C5:C7)) | D32: =IF(A32>7.65,C32-REFERENCE!B5,C32+REFERENCE!B5) | E32: =IF(AND(B32,GAME!C32<>""),EXP(-((C32-GAME!C32)^2)/(2*GAME!F5^2)),0) | F32: =IF(AND(B32,GAME!C32<>""),EXP(-((D32-GAME!C32)^2)/(2*GAME!F5^2)),0) | G32: =IF(GAME!C32="",IF(B32,1/COUNTIF(B23:B39,TRUE),0),IF(B32,(GAME!F4*E32+(1-GAME!F4)*F32)/SUMPRODUCT(GAME!F4*E23:E39+(1-GAME!F4)*F23:F39),0))
A33: 10 | B33: =AND(A33<>GAME!C4,OR(GAME!C5="",A33<>GAME!C5),OR(GAME!C6="",A33<>GAME!C6),OR(GAME!C7="",A33<>GAME!C7)) | C33: =A33+SUM(GAME!C5:C7)+(7-COUNTA(GAME!C5:C7))*(130-A33-SUM(GAME!C5:C7))/(16-COUNTA(GAME!C5:C7)) | D33: =IF(A33>7.65,C33-REFERENCE!B5,C33+REFERENCE!B5) | E33: =IF(AND(B33,GAME!C32<>""),EXP(-((C33-GAME!C32)^2)/(2*GAME!F5^2)),0) | F33: =IF(AND(B33,GAME!C32<>""),EXP(-((D33-GAME!C32)^2)/(2*GAME!F5^2)),0) | G33: =IF(GAME!C32="",IF(B33,1/COUNTIF(B23:B39,TRUE),0),IF(B33,(GAME!F4*E33+(1-GAME!F4)*F33)/SUMPRODUCT(GAME!F4*E23:E39+(1-GAME!F4)*F23:F39),0))
A34: 11 | B34: =AND(A34<>GAME!C4,OR(GAME!C5="",A34<>GAME!C5),OR(GAME!C6="",A34<>GAME!C6),OR(GAME!C7="",A34<>GAME!C7)) | C34: =A34+SUM(GAME!C5:C7)+(7-COUNTA(GAME!C5:C7))*(130-A34-SUM(GAME!C5:C7))/(16-COUNTA(GAME!C5:C7)) | D34: =IF(A34>7.65,C34-REFERENCE!B5,C34+REFERENCE!B5) | E34: =IF(AND(B34,GAME!C32<>""),EXP(-((C34-GAME!C32)^2)/(2*GAME!F5^2)),0) | F34: =IF(AND(B34,GAME!C32<>""),EXP(-((D34-GAME!C32)^2)/(2*GAME!F5^2)),0) | G34: =IF(GAME!C32="",IF(B34,1/COUNTIF(B23:B39,TRUE),0),IF(B34,(GAME!F4*E34+(1-GAME!F4)*F34)/SUMPRODUCT(GAME!F4*E23:E39+(1-GAME!F4)*F23:F39),0))
A35: 12 | B35: =AND(A35<>GAME!C4,OR(GAME!C5="",A35<>GAME!C5),OR(GAME!C6="",A35<>GAME!C6),OR(GAME!C7="",A35<>GAME!C7)) | C35: =A35+SUM(GAME!C5:C7)+(7-COUNTA(GAME!C5:C7))*(130-A35-SUM(GAME!C5:C7))/(16-COUNTA(GAME!C5:C7)) | D35: =IF(A35>7.65,C35-REFERENCE!B5,C35+REFERENCE!B5) | E35: =IF(AND(B35,GAME!C32<>""),EXP(-((C35-GAME!C32)^2)/(2*GAME!F5^2)),0) | F35: =IF(AND(B35,GAME!C32<>""),EXP(-((D35-GAME!C32)^2)/(2*GAME!F5^2)),0) | G35: =IF(GAME!C32="",IF(B35,1/COUNTIF(B23:B39,TRUE),0),IF(B35,(GAME!F4*E35+(1-GAME!F4)*F35)/SUMPRODUCT(GAME!F4*E23:E39+(1-GAME!F4)*F23:F39),0))
A36: 13 | B36: =AND(A36<>GAME!C4,OR(GAME!C5="",A36<>GAME!C5),OR(GAME!C6="",A36<>GAME!C6),OR(GAME!C7="",A36<>GAME!C7)) | C36: =A36+SUM(GAME!C5:C7)+(7-COUNTA(GAME!C5:C7))*(130-A36-SUM(GAME!C5:C7))/(16-COUNTA(GAME!C5:C7)) | D36: =IF(A36>7.65,C36-REFERENCE!B5,C36+REFERENCE!B5) | E36: =IF(AND(B36,GAME!C32<>""),EXP(-((C36-GAME!C32)^2)/(2*GAME!F5^2)),0) | F36: =IF(AND(B36,GAME!C32<>""),EXP(-((D36-GAME!C32)^2)/(2*GAME!F5^2)),0) | G36: =IF(GAME!C32="",IF(B36,1/COUNTIF(B23:B39,TRUE),0),IF(B36,(GAME!F4*E36+(1-GAME!F4)*F36)/SUMPRODUCT(GAME!F4*E23:E39+(1-GAME!F4)*F23:F39),0))
A37: 14 | B37: =AND(A37<>GAME!C4,OR(GAME!C5="",A37<>GAME!C5),OR(GAME!C6="",A37<>GAME!C6),OR(GAME!C7="",A37<>GAME!C7)) | C37: =A37+SUM(GAME!C5:C7)+(7-COUNTA(GAME!C5:C7))*(130-A37-SUM(GAME!C5:C7))/(16-COUNTA(GAME!C5:C7)) | D37: =IF(A37>7.65,C37-REFERENCE!B5,C37+REFERENCE!B5) | E37: =IF(AND(B37,GAME!C32<>""),EXP(-((C37-GAME!C32)^2)/(2*GAME!F5^2)),0) | F37: =IF(AND(B37,GAME!C32<>""),EXP(-((D37-GAME!C32)^2)/(2*GAME!F5^2)),0) | G37: =IF(GAME!C32="",IF(B37,1/COUNTIF(B23:B39,TRUE),0),IF(B37,(GAME!F4*E37+(1-GAME!F4)*F37)/SUMPRODUCT(GAME!F4*E23:E39+(1-GAME!F4)*F23:F39),0))
A38: 15 | B38: =AND(A38<>GAME!C4,OR(GAME!C5="",A38<>GAME!C5),OR(GAME!C6="",A38<>GAME!C6),OR(GAME!C7="",A38<>GAME!C7)) | C38: =A38+SUM(GAME!C5:C7)+(7-COUNTA(GAME!C5:C7))*(130-A38-SUM(GAME!C5:C7))/(16-COUNTA(GAME!C5:C7)) | D38: =IF(A38>7.65,C38-REFERENCE!B5,C38+REFERENCE!B5) | E38: =IF(AND(B38,GAME!C32<>""),EXP(-((C38-GAME!C32)^2)/(2*GAME!F5^2)),0) | F38: =IF(AND(B38,GAME!C32<>""),EXP(-((D38-GAME!C32)^2)/(2*GAME!F5^2)),0) | G38: =IF(GAME!C32="",IF(B38,1/COUNTIF(B23:B39,TRUE),0),IF(B38,(GAME!F4*E38+(1-GAME!F4)*F38)/SUMPRODUCT(GAME!F4*E23:E39+(1-GAME!F4)*F23:F39),0))
A39: 20 | B39: =AND(A39<>GAME!C4,OR(GAME!C5="",A39<>GAME!C5),OR(GAME!C6="",A39<>GAME!C6),OR(GAME!C7="",A39<>GAME!C7)) | C39: =A39+SUM(GAME!C5:C7)+(7-COUNTA(GAME!C5:C7))*(130-A39-SUM(GAME!C5:C7))/(16-COUNTA(GAME!C5:C7)) | D39: =IF(A39>7.65,C39-REFERENCE!B5,C39+REFERENCE!B5) | E39: =IF(AND(B39,GAME!C32<>""),EXP(-((C39-GAME!C32)^2)/(2*GAME!F5^2)),0) | F39: =IF(AND(B39,GAME!C32<>""),EXP(-((D39-GAME!C32)^2)/(2*GAME!F5^2)),0) | G39: =IF(GAME!C32="",IF(B39,1/COUNTIF(B23:B39,TRUE),0),IF(B39,(GAME!F4*E39+(1-GAME!F4)*F39)/SUMPRODUCT(GAME!F4*E23:E39+(1-GAME!F4)*F23:F39),0))
A40: Opponent 3 | C40: Obs Mid → GAME!C33
A41: Card | B41: Poss? | C41: Naive EV | D41: Bluff EV | E41: L(naive) | F41: L(bluff) | G41: P(card)
...

Sheet REFERENCE
A1: REFERENCE DATA
A3: Settings | D3: Deck Stats
A4: Sigma: | B4: =GAME!F5 | D4: Total Cards: | E4: 17
A5: Bluff Offset: | B5: 6 | D5: Deck Sum: | E5: 130
A6: Bluff Prior (p): | B6: =GAME!F4 | D6: Mean per Card: | E6: 7.65
D7: Cards in Play: | E7: 8
A8: Deck | D8: Players: | E8: 5
A9: Card | B9: Mean Excl.
A10: -10 | B10: 8.75
A11: 1 | B11: 8.06
A12: 2 | B12: 8
A13: 3 | B13: 7.94
A14: 4 | B14: 7.88
A15: 5 | B15: 7.81
A16: 6 | B16: 7.75
A17: 7 | B17: 7.69
A18: 8 | B18: 7.62
A19: 9 | B19: 7.56
A20: 10 | B20: 7.5
A21: 11 | B21: 7.44
... A26: 20 | B26: 6.88
A29: HOW TO USE
A30: 1. Enter your card in the yellow cell on GAME sheet
A31: 2. As central cards are revealed, enter them
A32: 3. When an opponent quotes, enter their mid-price
A33: 4. When offered a price, enter bid/ask in Decision Helper
A34: 5. The sheet tells you: fair price, who has what, buy/sell/walk
A36: p=1.0 → assume no bluffing. p=0.5 → uncertain. p=0.0 → everyone bluffs.
A37: Sigma: lower = more confident inference (try 2-4)
A38: Bluff Offset: how far bluffers shift from true EV (try 4-8)
